Workbook

Sheet AM & AS
B1: RUMUS | C1: =COUNTIFS(TOKO!$C:$C,'AM & AS'!$A:$A,TOKO!$F:$F,'AM & AS'!$B:$B) -> 0 | D1: =COUNTIFS(TOKO!$C:$C,'AM & AS'!$A:$A,TOKO!$F:$F,'AM & AS'!$B:$B,TOKO!$K:$K,"=0") -> 0 | E1: =COUNTIFS(TOKO!$C:$C,'AM & AS'!$A:$A,TOKO!$F:$F,'AM & AS'!$B:$B,TOKO!$K:$K,">0") -> 0 | F1: =COUNTIFS(TOKO!$C:$C,'AM & AS'!$A:$A,TOKO!$F:$F,'AM & AS'!$B:$B,TOKO!$L:$L,"<100") -> 0 | G1: =SUMIFS(TOKO!$I:$I,TOKO!$C:$C,'AM & AS'!$A:$A,TOKO!$F:$F,'AM & AS'!$B:$B) -> 0 | H1: =SUMIFS(TOKO!$J:$J,TOKO!$C:$C,'AM & AS'!$A:$A,TOKO!$F:$F,'AM & AS'!$B:$B) -> 0 | I1: =SUMIFS(TOKO!$K:$K,TOKO!$C:$C,'AM & AS'!$A:$A,TOKO!$F:$F,'AM & AS'!$B:$B) -> 0 | J1: =I1/G1*100 -> #DIV/0!
A3: REPORT PENCAPAIAN ICE CREAM & TELUR
A4: REALTIME | L4: NOTE
A5: CAB JEMBER | L5: JIKA MAU SHORT MATIKAN RUMUS
A6: AM | B6: MODUL | C6: TOKO | D6: TOKO TIDAK ADA SALES | E6: TOKO ADA SALES | F6: ACH <100% | G6: TARGET | H6: STOK | I6: REALTIME | J6: ACH | L6: RUMUS SUDAH TERSEDIA DI ATAS
A7: ATS | B7: SOSIS | C7: =COUNTIFS(TOKO!$C:$C,'AM & AS'!$A:$A,TOKO!$F:$F,'AM & AS'!$B:$B) -> 0 | D7: =COUNTIFS(TOKO!$C:$C,'AM & AS'!$A:$A,TOKO!$F:$F,'AM & AS'!$B:$B,TOKO!$K:$K,"=0") -> 0 | E7: =COUNTIFS(TOKO!$C:$C,'AM & AS'!$A:$A,TOKO!$F:$F,'AM & AS'!$B:$B,TOKO!$K:$K,">0") -> 0 | F7: =COUNTIFS(TOKO!$C:$C,'AM & AS'!$A:$A,TOKO!$F:$F,'AM & AS'!$B:$B,TOKO!$L:$L,"<100") -> 0 | G7: =SUMIFS(TOKO!$I:$I,TOKO!$C:$C,'AM & AS'!$A:$A,TOKO!$F:$F,'AM & AS'!$B:$B) -> 0 | H7: =SUMIFS(TOKO!$J:$J,TOKO!$C:$C,'AM & AS'!$A:$A,TOKO!$F:$F,'AM & AS'!$B:$B) -> 0 | I7: =SUMIFS(TOKO!$K:$K,TOKO!$C:$C,'AM & AS'!$A:$A,TOKO!$F:$F,'AM & AS'!$B:$B) -> 0 | J7: =I7/G7*100 -> #DIV/0!
A8: ESY | B8: SOSIS | C8: =COUNTIFS(TOKO!$C:$C,'AM & AS'!$A:$A,TOKO!$F:$F,'AM & AS'!$B:$B) -> 0 | D8: =COUNTIFS(TOKO!$C:$C,'AM & AS'!$A:$A,TOKO!$F:$F,'AM & AS'!$B:$B,TOKO!$K:$K,"=0") -> 0 | E8: =COUNTIFS(TOKO!$C:$C,'AM & AS'!$A:$A,TOKO!$F:$F,'AM & AS'!$B:$B,TOKO!$K:$K,">0") -> 0 | F8: =COUNTIFS(TOKO!$C:$C,'AM & AS'!$A:$A,TOKO!$F:$F,'AM & AS'!$B:$B,TOKO!$L:$L,"<100") -> 0 | G8: =SUMIFS(TOKO!$I:$I,TOKO!$C:$C,'AM & AS'!$A:$A,TOKO!$F:$F,'AM & AS'!$B:$B) -> 0 | H8: =SUMIFS(TOKO!$J:$J,TOKO!$C:$C,'AM & AS'!$A:$A,TOKO!$F:$F,'AM & AS'!$B:$B) -> 0 | I8: =SUMIFS(TOKO!$K:$K,TOKO!$C:$C,'AM & AS'!$A:$A,TOKO!$F:$F,'AM & AS'!$B:$B) -> 0 | J8: =I8/G8*100 -> #DIV/0!
A9: JDP | B9: SOSIS | C9: =COUNTIFS(TOKO!$C:$C,'AM & AS'!$A:$A,TOKO!$F:$F,'AM & AS'!$B:$B) -> 0 | D9: =COUNTIFS(TOKO!$C:$C,'AM & AS'!$A:$A,TOKO!$F:$F,'AM & AS'!$B:$B,TOKO!$K:$K,"=0") -> 0 | E9: =COUNTIFS(TOKO!$C:$C,'AM & AS'!$A:$A,TOKO!$F:$F,'AM & AS'!$B:$B,TOKO!$K:$K,">0") -> 0 | F9: =COUNTIFS(TOKO!$C:$C,'AM & AS'!$A:$A,TOKO!$F:$F,'AM & AS'!$B:$B,TOKO!$L:$L,"<100") -> 0 | G9: =SUMIFS(TOKO!$I:$I,TOKO!$C:$C,'AM & AS'!$A:$A,TOKO!$F:$F,'AM & AS'!$B:$B) -> 0 | H9: =SUMIFS(TOKO!$J:$J,TOKO!$C:$C,'AM & AS'!$A:$A,TOKO!$F:$F,'AM & AS'!$B:$B) -> 0 | I9: =SUMIFS(TOKO!$K:$K,TOKO!$C:$C,'AM & AS'!$A:$A,TOKO!$F:$F,'AM & AS'!$B:$B) -> 0 | J9: =I9/G9*100 -> #DIV/0!
A10: JLE | B10: SOSIS | C10: =COUNTIFS(TOKO!$C:$C,'AM & AS'!$A:$A,TOKO!$F:$F,'AM & AS'!$B:$B) -> 41 | D10: =COUNTIFS(TOKO!$C:$C,'AM & AS'!$A:$A,TOKO!$F:$F,'AM & AS'!$B:$B,TOKO!$K:$K,"=0") -> 0 | E10: =COUNTIFS(TOKO!$C:$C,'AM & AS'!$A:$A,TOKO!$F:$F,'AM & AS'!$B:$B,TOKO!$K:$K,">0") -> 0 | F10: =COUNTIFS(TOKO!$C:$C,'AM & AS'!$A:$A,TOKO!$F:$F,'AM & AS'!$B:$B,TOKO!$L:$L,"<100") -> 0 | G10: =SUMIFS(TOKO!$I:$I,TOKO!$C:$C,'AM & AS'!$A:$A,TOKO!$F:$F,'AM & AS'!$B:$B) -> 1137.0251 | H10: =SUMIFS(TOKO!$J:$J,TOKO!$C:$C,'AM & AS'!$A:$A,TOKO!$F:$F,'AM & AS'!$B:$B) -> 0 | I10: =SUMIFS(TOKO!$K:$K,TOKO!$C:$C,'AM & AS'!$A:$A,TOKO!$F:$F,'AM & AS'!$B:$B) -> 0 | J10: =I10/G10*100 -> 0
A11: KAM | B11: SOSIS | C11: =COUNTIFS(TOKO!$C:$C,'AM & AS'!$A:$A,TOKO!$F:$F,'AM & AS'!$B:$B) -> 0 | D11: =COUNTIFS(TOKO!$C:$C,'AM & AS'!$A:$A,TOKO!$F:$F,'AM & AS'!$B:$B,TOKO!$K:$K,"=0") -> 0 | E11: =COUNTIFS(TOKO!$C:$C,'AM & AS'!$A:$A,TOKO!$F:$F,'AM & AS'!$B:$B,TOKO!$K:$K,">0") -> 0 | F11: =COUNTIFS(TOKO!$C:$C,'AM & AS'!$A:$A,TOKO!$F:$F,'AM & AS'!$B:$B,TOKO!$L:$L,"<100") -> 0 | G11: =SUMIFS(TOKO!$I:$I,TOKO!$C:$C,'AM & AS'!$A:$A,TOKO!$F:$F,'AM & AS'!$B:$B) -> 0 | H11: =SUMIFS(TOKO!$J:$J,TOKO!$C:$C,'AM & AS'!$A:$A,TOKO!$F:$F,'AM & AS'!$B:$B) -> 0 | I11: =SUMIFS(TOKO!$K:$K,TOKO!$C:$C,'AM & AS'!$A:$A,TOKO!$F:$F,'AM & AS'!$B:$B) -> 0 | J11: =I11/G11*100 -> #DIV/0!
A12: RFK | B12: SOSIS | C12: =COUNTIFS(TOKO!$C:$C,'AM & AS'!$A:$A,TOKO!$F:$F,'AM & AS'!$B:$B) -> 44 | D12: =COUNTIFS(TOKO!$C:$C,'AM & AS'!$A:$A,TOKO!$F:$F,'AM & AS'!$B:$B,TOKO!$K:$K,"=0") -> 0 | E12: =COUNTIFS(TOKO!$C:$C,'AM & AS'!$A:$A,TOKO!$F:$F,'AM & AS'!$B:$B,TOKO!$K:$K,">0") -> 0 | F12: =COUNTIFS(TOKO!$C:$C,'AM & AS'!$A:$A,TOKO!$F:$F,'AM & AS'!$B:$B,TOKO!$L:$L,"<100") -> 0 | G12: =SUMIFS(TOKO!$I:$I,TOKO!$C:$C,'AM & AS'!$A:$A,TOKO!$F:$F,'AM & AS'!$B:$B) -> 681.60292 | H12: =SUMIFS(TOKO!$J:$J,TOKO!$C:$C,'AM & AS'!$A:$A,TOKO!$F:$F,'AM & AS'!$B:$B) -> 0 | I12: =SUMIFS(TOKO!$K:$K,TOKO!$C:$C,'AM & AS'!$A:$A,TOKO!$F:$F,'AM & AS'!$B:$B) -> 0 | J12: =I12/G12*100 -> 0
A13: SBN | B13: SOSIS | C13: =COUNTIFS(TOKO!$C:$C,'AM & AS'!$A:$A,TOKO!$F:$F,'AM & AS'!$B:$B) -> 0 | D13: =COUNTIFS(TOKO!$C:$C,'AM & AS'!$A:$A,TOKO!$F:$F,'AM & AS'!$B:$B,TOKO!$K:$K,"=0") -> 0 | E13: =COUNTIFS(TOKO!$C:$C,'AM & AS'!$A:$A,TOKO!$F:$F,'AM & AS'!$B:$B,TOKO!$K:$K,">0") -> 0 | F13: =COUNTIFS(TOKO!$C:$C,'AM & AS'!$A:$A,TOKO!$F:$F,'AM & AS'!$B:$B,TOKO!$L:$L,"<100") -> 0 | G13: =SUMIFS(TOKO!$I:$I,TOKO!$C:$C,'AM & AS'!$A:$A,TOKO!$F:$F,'AM & AS'!$B:$B) -> 0 | H13: =SUMIFS(TOKO!$J:$J,TOKO!$C:$C,'AM & AS'!$A:$A,TOKO!$F:$F,'AM & AS'!$B:$B) -> 0 | I13: =SUMIFS(TOKO!$K:$K,TOKO!$C:$C,'AM & AS'!$A:$A,TOKO!$F:$F,'AM & AS'!$B:$B) -> 0 | J13: =I13/G13*100 -> #DIV/0!
A14: SSO | B14: SOSIS | C14: =COUNTIFS(TOKO!$C:$C,'AM & AS'!$A:$A,TOKO!$F:$F,'AM & AS'!$B:$B) -> 0 | D14: =COUNTIFS(TOKO!$C:$C,'AM & AS'!$A:$A,TOKO!$F:$F,'AM & AS'!$B:$B,TOKO!$K:$K,"=0") -> 0 | E14: =COUNTIFS(TOKO!$C:$C,'AM & AS'!$A:$A,TOKO!$F:$F,'AM & AS'!$B:$B,TOKO!$K:$K,">0") -> 0 | F14: =COUNTIFS(TOKO!$C:$C,'AM & AS'!$A:$A,TOKO!$F:$F,'AM & AS'!$B:$B,TOKO!$L:$L,"<100") -> 0 | G14: =SUMIFS(TOKO!$I:$I,TOKO!$C:$C,'AM & AS'!$A:$A,TOKO!$F:$F,'AM & AS'!$B:$B) -> 0 | H14: =SUMIFS(TOKO!$J:$J,TOKO!$C:$C,'AM & AS'!$A:$A,TOKO!$F:$F,'AM & AS'!$B:$B) -> 0 | I14: =SUMIFS(TOKO!$K:$K,TOKO!$C:$C,'AM & AS'!$A:$A,TOKO!$F:$F,'AM & AS'!$B:$B) -> 0 | J14: =I14/G14*100 -> #DIV/0!
A15: SUR | B15: SOSIS | C15: =COUNTIFS(TOKO!$C:$C,'AM & AS'!$A:$A,TOKO!$F:$F,'AM & AS'!$B:$B) -> 0 | D15: =COUNTIFS(TOKO!$C:$C,'AM & AS'!$A:$A,TOKO!$F:$F,'AM & AS'!$B:$B,TOKO!$K:$K,"=0") -> 0 | E15: =COUNTIFS(TOKO!$C:$C,'AM & AS'!$A:$A,TOKO!$F:$F,'AM & AS'!$B:$B,TOKO!$K:$K,">0") -> 0 | F15: =COUNTIFS(TOKO!$C:$C,'AM & AS'!$A:$A,TOKO!$F:$F,'AM & AS'!$B:$B,TOKO!$L:$L,"<100") -> 0 | G15: =SUMIFS(TOKO!$I:$I,TOKO!$C:$C,'AM & AS'!$A:$A,TOKO!$F:$F,'AM & AS'!$B:$B) -> 0 | H15: =SUMIFS(TOKO!$J:$J,TOKO!$C:$C,'AM & AS'!$A:$A,TOKO!$F:$F,'AM & AS'!$B:$B) -> 0 | I15: =SUMIFS(TOKO!$K:$K,TOKO!$C:$C,'AM & AS'!$A:$A,TOKO!$F:$F,'AM & AS'!$B:$B) -> 0 | J15: =I15/G15*100 -> #DIV/0!
A16: SYA | B16: SOSIS | C16: =COUNTIFS(TOKO!$C:$C,'AM & AS'!$A:$A,TOKO!$F:$F,'AM & AS'!$B:$B) -> 0 | D16: =COUNTIFS(TOKO!$C:$C,'AM & AS'!$A:$A,TOKO!$F:$F,'AM & AS'!$B:$B,TOKO!$K:$K,"=0") -> 0 | E16: =COUNTIFS(TOKO!$C:$C,'AM & AS'!$A:$A,TOKO!$F:$F,'AM & AS'!$B:$B,TOKO!$K:$K,">0") -> 0 | F16: =COUNTIFS(TOKO!$C:$C,'AM & AS'!$A:$A,TOKO!$F:$F,'AM & AS'!$B:$B,TOKO!$L:$L,"<100") -> 0 | G16: =SUMIFS(TOKO!$I:$I,TOKO!$C:$C,'AM & AS'!$A:$A,TOKO!$F:$F,'AM & AS'!$B:$B) -> 0 | H16: =SUMIFS(TOKO!$J:$J,TOKO!$C:$C,'AM & AS'!$A:$A,TOKO!$F:$F,'AM & AS'!$B:$B) -> 0 | I16: =SUMIFS(TOKO!$K:$K,TOKO!$C:$C,'AM & AS'!$A:$A,TOKO!$F:$F,'AM & AS'!$B:$B) -> 0 | J16: =I16/G16*100 -> #DIV/0!
A17: ATS | B17: FRIED CHICKEN | C17: =COUNTIFS(TOKO!$C:$C,'AM & AS'!$A:$A,TOKO!$F:$F,'AM & AS'!$B:$B) -> 0 | D17: =COUNTIFS(TOKO!$C:$C,'AM & AS'!$A:$A,TOKO!$F:$F,'AM & AS'!$B:$B,TOKO!$K:$K,"=0") -> 0 | E17: =COUNTIFS(TOKO!$C:$C,'AM & AS'!$A:$A,TOKO!$F:$F,'AM & AS'!$B:$B,TOKO!$K:$K,">0") -> 0 | F17: =COUNTIFS(TOKO!$C:$C,'AM & AS'!$A:$A,TOKO!$F:$F,'AM & AS'!$B:$B,TOKO!$L:$L,"<100") -> 0 | G17: =SUMIFS(TOKO!$I:$I,TOKO!$C:$C,'AM & AS'!$A:$A,TOKO!$F:$F,'AM & AS'!$B:$B) -> 0 | H17: =SUMIFS(TOKO!$J:$J,TOKO!$C:$C,'AM & AS'!$A:$A,TOKO!$F:$F,'AM & AS'!$B:$B) -> 0 | I17: =SUMIFS(TOKO!$K:$K,TOKO!$C:$C,'AM & AS'!$A:$A,TOKO!$F:$F,'AM & AS'!$B:$B) -> 0 | J17: =I17/G17*100 -> #DIV/0!
A18: ESY | B18: FRIED CHICKEN | C18: =COUNTIFS(TOKO!$C:$C,'AM & AS'!$A:$A,TOKO!$F:$F,'AM & AS'!$B:$B) -> 0 | D18: =COUNTIFS(TOKO!$C:$C,'AM & AS'!$A:$A,TOKO!$F:$F,'AM & AS'!$B:$B,TOKO!$K:$K,"=0") -> 0 | E18: =COUNTIFS(TOKO!$C:$C,'AM & AS'!$A:$A,TOKO!$F:$F,'AM & AS'!$B:$B,TOKO!$K:$K,">0") -> 0 | F18: =COUNTIFS(TOKO!$C:$C,'AM & AS'!$A:$A,TOKO!$F:$F,'AM & AS'!$B:$B,TOKO!$L:$L,"<100") -> 0 | G18: =SUMIFS(TOKO!$I:$I,TOKO!$C:$C,'AM & AS'!$A:$A,TOKO!$F:$F,'AM & AS'!$B:$B) -> 0 | H18: =SUMIFS(TOKO!$J:$J,TOKO!$C:$C,'AM & AS'!$A:$A,TOKO!$F:$F,'AM & AS'!$B:$B) -> 0 | I18: =SUMIFS(TOKO!$K:$K,TOKO!$C:$C,'AM & AS'!$A:$A,TOKO!$F:$F,'AM & AS'!$B:$B) -> 0 | J18: =I18/G18*100 -> #DIV/0!
... A26: SYA | B26: FRIED CHICKEN | C26: =COUNTIFS(TOKO!$C:$C,'AM & AS'!$A:$A,TOKO!$F:$F,'AM & AS'!$B:$B) -> 0 | D26: =COUNTIFS(TOKO!$C:$C,'AM & AS'!$A:$A,TOKO!$F:$F,'AM & AS'!$B:$B,TOKO!$K:$K,"=0") -> 0 | E26: =COUNTIFS(TOKO!$C:$C,'AM & AS'!$A:$A,TOKO!$F:$F,'AM & AS'!$B:$B,TOKO!$K:$K,">0") -> 0 | F26: =COUNTIFS(TOKO!$C:$C,'AM & AS'!$A:$A,TOKO!$F:$F,'AM & AS'!$B:$B,TOKO!$L:$L,"<100") -> 0 | G26: =SUMIFS(TOKO!$I:$I,TOKO!$C:$C,'AM & AS'!$A:$A,TOKO!$F:$F,'AM & AS'!$B:$B) -> 0 | H26: =SUMIFS(TOKO!$J:$J,TOKO!$C:$C,'AM & AS'!$A:$A,TOKO!$F:$F,'AM & AS'!$B:$B) -> 0 | I26: =SUMIFS(TOKO!$K:$K,TOKO!$C:$C,'AM & AS'!$A:$A,TOKO!$F:$F,'AM & AS'!$B:$B) -> 0 | J26: =I26/G26*100 -> #DIV/0!
A27: Grand Total | C27: =SUM(C7:C26) -> 156 | D27: =SUM(D7:D26) -> 28 | E27: =SUM(E7:E26) -> 43 | F27: =SUM(F7:F26) -> 71 | G27: =SUM(G7:G26) -> 5732.0796 | H27: =SUM(H7:H26) -> 0 | I27: =SUM(I7:I26) -> 205 | J27: =I27/G27*100 -> 3.5763634
B29: RUMUS | C29: =COUNTIFS(TOKO!$D:$D,'AM & AS'!$A:$A,TOKO!$F:$F,'AM & AS'!$B:$B) -> 0 | D29: =COUNTIFS(TOKO!$D:$D,'AM & AS'!$A:$A,TOKO!$F:$F,'AM & AS'!$B:$B,TOKO!$K:$K,"=0") -> 0 | E29: =COUNTIFS(TOKO!$D:$D,'AM & AS'!$A:$A,TOKO!$F:$F,'AM & AS'!$B:$B,TOKO!$K:$K,">0") -> 0 | F29: =COUNTIFS(TOKO!$D:$D,'AM & AS'!$A:$A,TOKO!$F:$F,'AM & AS'!$B:$B,TOKO!$L:$L,"<100") -> 0 | G29: =SUMIFS(TOKO!$I:$I,TOKO!$D:$D,'AM & AS'!$A:$A,TOKO!$F:$F,'AM & AS'!$B:$B) -> 0 | H29: =SUMIFS(TOKO!$J:$J,TOKO!$D:$D,'AM & AS'!$A:$A,TOKO!$F:$F,'AM & AS'!$B:$B) -> 0 | I29: =SUMIFS(TOKO!$K:$K,TOKO!$D:$D,'AM & AS'!$A:$A,TOKO!$F:$F,'AM & AS'!$B:$B) -> 0 | J29: =I29/G29*100 -> #DIV/0!
A31: =A3 -> REPORT PENCAPAIAN ICE CREAM & TELUR
A32: =A4 -> REALTIME | L32: NOTE
A33: =A5 -> CAB JEMBER | L33: JIKA MAU SHORT MATIKAN RUMUS
A34: AM | B34: MODUL | C34: TOKO | D34: TOKO TIDAK ADA SALES | E34: TOKO ADA SALES | F34: ACH <100% | G34: TARGET | H34: STOK | I34: REALTIME | J34: ACH | L34: RUMUS SUDAH TERSEDIA DI ATAS
A35: RMB | B35: FRIED CHICKEN | C35: =COUNTIFS(TOKO!$D:$D,'AM & AS'!$A:$A,TOKO!$F:$F,'AM & AS'!$B:$B) -> 9 | D35: =COUNTIFS(TOKO!$D:$D,'AM & AS'!$A:$A,TOKO!$F:$F,'AM & AS'!$B:$B,TOKO!$K:$K,"=0") -> 5 | E35: =COUNTIFS(TOKO!$D:$D,'AM & AS'!$A:$A,TOKO!$F:$F,'AM & AS'!$B:$B,TOKO!$K:$K,">0") -> 4 | F35: =COUNTIFS(TOKO!$D:$D,'AM & AS'!$A:$A,TOKO!$F:$F,'AM & AS'!$B:$B,TOKO!$L:$L,"<100") -> 9 | G35: =SUMIFS(TOKO!$I:$I,TOKO!$D:$D,'AM & AS'!$A:$A,TOKO!$F:$F,'AM & AS'!$B:$B) -> 411.19355 | H35: =SUMIFS(TOKO!$J:$J,TOKO!$D:$D,'AM & AS'!$A:$A,TOKO!$F:$F,'AM & AS'!$B:$B) -> 0 | I35: =SUMIFS(TOKO!$K:$K,TOKO!$D:$D,'AM & AS'!$A:$A,TOKO!$F:$F,'AM & AS'!$B:$B) -> 23 | J35: =I35/G35*100 -> 5.593473
A36: RMB | B36: SOSIS | C36: =COUNTIFS(TOKO!$D:$D,'AM & AS'!$A:$A,TOKO!$F:$F,'AM & AS'!$B:$B) -> 11 | D36: =COUNTIFS(TOKO!$D:$D,'AM & AS'!$A:$A,TOKO!$F:$F,'AM & AS'!$B:$B,TOKO!$K:$K,"=0") -> 0 | E36: =COUNTIFS(TOKO!$D:$D,'AM & AS'!$A:$A,TOKO!$F:$F,'AM & AS'!$B:$B,TOKO!$K:$K,">0") -> 0 | F36: =COUNTIFS(TOKO!$D:$D,'AM & AS'!$A:$A,TOKO!$F:$F,'AM & AS'!$B:$B,TOKO!$L:$L,"<100") -> 0 | G36: =SUMIFS(TOKO!$I:$I,TOKO!$D:$D,'AM & AS'!$A:$A,TOKO!$F:$F,'AM & AS'!$B:$B) -> 188.61382 | H36: =SUMIFS(TOKO!$J:$J,TOKO!$D:$D,'AM & AS'!$A:$A,TOKO!$F:$F,'AM & AS'!$B:$B) -> 0 | I36: =SUMIFS(TOKO!$K:$K,TOKO!$D:$D,'AM & AS'!$A:$A,TOKO!$F:$F,'AM & AS'!$B:$B) -> 0 | J36: =I36/G36*100 -> 0
A37: INK | B37: FRIED CHICKEN | C37: =COUNTIFS(TOKO!$D:$D,'AM & AS'!$A:$A,TOKO!$F:$F,'AM & AS'!$B:$B) -> 8 | D37: =COUNTIFS(TOKO!$D:$D,'AM & AS'!$A:$A,TOKO!$F:$F,'AM & AS'!$B:$B,TOKO!$K:$K,"=0") -> 3 | E37: =COUNTIFS(TOKO!$D:$D,'AM & AS'!$A:$A,TOKO!$F:$F,'AM & AS'!$B:$B,TOKO!$K:$K,">0") -> 5 | F37: =COUNTIFS(TOKO!$D:$D,'AM & AS'!$A:$A,TOKO!$F:$F,'AM & AS'!$B:$B,TOKO!$L:$L,"<100") -> 8 | G37: =SUMIFS(TOKO!$I:$I,TOKO!$D:$D,'AM & AS'!$A:$A,TOKO!$F:$F,'AM & AS'!$B:$B) -> 327.96774 | H37: =SUMIFS(TOKO!$J:$J,TOKO!$D:$D,'AM & AS'!$A:$A,TOKO!$F:$F,'AM & AS'!$B:$B) -> 0 | I37: =SUMIFS(TOKO!$K:$K,TOKO!$D:$D,'AM & AS'!$A:$A,TOKO!$F:$F,'AM & AS'!$B:$B) -> 16 | J37: =I37/G37*100 -> 4.8785286
A38: INK | B38: SOSIS | C38: =COUNTIFS(TOKO!$D:$D,'AM & AS'!$A:$A,TOKO!$F:$F,'AM & AS'!$B:$B) -> 12 | D38: =COUNTIFS(TOKO!$D:$D,'AM & AS'!$A:$A,TOKO!$F:$F,'AM & AS'!$B:$B,TOKO!$K:$K,"=0") -> 0 | E38: =COUNTIFS(TOKO!$D:$D,'AM & AS'!$A:$A,TOKO!$F:$F,'AM & AS'!$B:$B,TOKO!$K:$K,">0") -> 0 | F38: =COUNTIFS(TOKO!$D:$D,'AM & AS'!$A:$A,TOKO!$F:$F,'AM & AS'!$B:$B,TOKO!$L:$L,"<100") -> 0 | G38: =SUMIFS(TOKO!$I:$I,TOKO!$D:$D,'AM & AS'!$A:$A,TOKO!$F:$F,'AM & AS'!$B:$B) -> 148.13246 | H38: =SUMIFS(TOKO!$J:$J,TOKO!$D:$D,'AM & AS'!$A:$A,TOKO!$F:$F,'AM & AS'!$B:$B) -> 0 | I38: =SUMIFS(TOKO!$K:$K,TOKO!$D:$D,'AM & AS'!$A:$A,TOKO!$F:$F,'AM & AS'!$B:$B) -> 0 | J38: =I38/G38*100 -> 0
A39: SGY | B39: FRIED CHICKEN | C39: =COUNTIFS(TOKO!$D:$D,'AM & AS'!$A:$A,TOKO!$F:$F,'AM & AS'!$B:$B) -> 11 | D39: =COUNTIFS(TOKO!$D:$D,'AM & AS'!$A:$A,TOKO!$F:$F,'AM & AS'!$B:$B,TOKO!$K:$K,"=0") -> 6 | E39: =COUNTIFS(TOKO!$D:$D,'AM & AS'!$A:$A,TOKO!$F:$F,'AM & AS'!$B:$B,TOKO!$K:$K,">0") -> 5 | F39: =COUNTIFS(TOKO!$D:$D,'AM & AS'!$A:$A,TOKO!$F:$F,'AM & AS'!$B:$B,TOKO!$L:$L,"<100") -> 11 | G39: =SUMIFS(TOKO!$I:$I,TOKO!$D:$D,'AM & AS'!$A:$A,TOKO!$F:$F,'AM & AS'!$B:$B) -> 346.74194 | H39: =SUMIFS(TOKO!$J:$J,TOKO!$D:$D,'AM & AS'!$A:$A,TOKO!$F:$F,'AM & AS'!$B:$B) -> 0 | I39: =SUMIFS(TOKO!$K:$K,TOKO!$D:$D,'AM & AS'!$A:$A,TOKO!$F:$F,'AM & AS'!$B:$B) -> 21 | J39: =I39/G39*100 -> 6.0563773
A40: SGY | B40: SOSIS | C40: =COUNTIFS(TOKO!$D:$D,'AM & AS'!$A:$A,TOKO!$F:$F,'AM & AS'!$B:$B) -> 12 | D40: =COUNTIFS(TOKO!$D:$D,'AM & AS'!$A:$A,TOKO!$F:$F,'AM & AS'!$B:$B,TOKO!$K:$K,"=0") -> 0 | E40: =COUNTIFS(TOKO!$D:$D,'AM & AS'!$A:$A,TOKO!$F:$F,'AM & AS'!$B:$B,TOKO!$K:$K,">0") -> 0 | F40: =COUNTIFS(TOKO!$D:$D,'AM & AS'!$A:$A,TOKO!$F:$F,'AM & AS'!$B:$B,TOKO!$L:$L,"<100") -> 0 | G40: =SUMIFS(TOKO!$I:$I,TOKO!$D:$D,'AM & AS'!$A:$A,TOKO!$F:$F,'AM & AS'!$B:$B) -> 186.30665 | H40: =SUMIFS(TOKO!$J:$J,TOKO!$D:$D,'AM & AS'!$A:$A,TOKO!$F:$F,'AM & AS'!$B:$B) -> 0 | I40: =SUMIFS(TOKO!$K:$K,TOKO!$D:$D,'AM & AS'!$A:$A,TOKO!$F:$F,'AM & AS'!$B:$B) -> 0 | J40: =I40/G40*100 -> 0
A41: PJO | B41: FRIED CHICKEN | C41: =COUNTIFS(TOKO!$D:$D,'AM & AS'!$A:$A,TOKO!$F:$F,'AM & AS'!$B:$B) -> 9 | D41: =COUNTIFS(TOKO!$D:$D,'AM & AS'!$A:$A,TOKO!$F:$F,'AM & AS'!$B:$B,TOKO!$K:$K,"=0") -> 3 | E41: =COUNTIFS(TOKO!$D:$D,'AM & AS'!$A:$A,TOKO!$F:$F,'AM & AS'!$B:$B,TOKO!$K:$K,">0") -> 6 | F41: =COUNTIFS(TOKO!$D:$D,'AM & AS'!$A:$A,TOKO!$F:$F,'AM & AS'!$B:$B,TOKO!$L:$L,"<100") -> 9 | G41: =SUMIFS(TOKO!$I:$I,TOKO!$D:$D,'AM & AS'!$A:$A,TOKO!$F:$F,'AM & AS'!$B:$B) -> 361.16129 | H41: =SUMIFS(TOKO!$J:$J,TOKO!$D:$D,'AM & AS'!$A:$A,TOKO!$F:$F,'AM & AS'!$B:$B) -> 0 | I41: =SUMIFS(TOKO!$K:$K,TOKO!$D:$D,'AM & AS'!$A:$A,TOKO!$F:$F,'AM & AS'!$B:$B) -> 38 | J41: =I41/G41*100 -> 10.521615
A42: PJO | B42: SOSIS | C42: =COUNTIFS(TOKO!$D:$D,'AM & AS'!$A:$A,TOKO!$F:$F,'AM & AS'!$B:$B) -> 9 | D42: =COUNTIFS(TOKO!$D:$D,'AM & AS'!$A:$A,TOKO!$F:$F,'AM & AS'!$B:$B,TOKO!$K:$K,"=0") -> 0 | E42: =COUNTIFS(TOKO!$D:$D,'AM & AS'!$A:$A,TOKO!$F:$F,'AM & AS'!$B:$B,TOKO!$K:$K,">0") -> 0 | F42: =COUNTIFS(TOKO!$D:$D,'AM & AS'!$A:$A,TOKO!$F:$F,'AM & AS'!$B:$B,TOKO!$L:$L,"<100") -> 0 | G42: =SUMIFS(TOKO!$I:$I,TOKO!$D:$D,'AM & AS'!$A:$A,TOKO!$F:$F,'AM & AS'!$B:$B) -> 158.54998 | H42: =SUMIFS(TOKO!$J:$J,TOKO!$D:$D,'AM & AS'!$A:$A,TOKO!$F:$F,'AM & AS'!$B:$B) -> 0 | I42: =SUMIFS(TOKO!$K:$K,TOKO!$D:$D,'AM & AS'!$A:$A,TOKO!$F:$F,'AM & AS'!$B:$B) -> 0 | J42: =I42/G42*100 -> 0
A43: EGR | B43: FRIED CHICKEN | C43: =COUNTIFS(TOKO!$D:$D,'AM & AS'!$A:$A,TOKO!$F:$F,'AM & AS'!$B:$B) -> 6 | D43: =COUNTIFS(TOKO!$D:$D,'AM & AS'!$A:$A,TOKO!$F:$F,'AM & AS'!$B:$B,TOKO!$K:$K,"=0") -> 3 | E43: =COUNTIFS(TOKO!$D:$D,'AM & AS'!$A:$A,TOKO!$F:$F,'AM & AS'!$B:$B,TOKO!$K:$K,">0") -> 3 | F43: =COUNTIFS(TOKO!$D:$D,'AM & AS'!$A:$A,TOKO!$F:$F,'AM & AS'!$B:$B,TOKO!$L:$L,"<100") -> 6 | G43: =SUMIFS(TOKO!$I:$I,TOKO!$D:$D,'AM & AS'!$A:$A,TOKO!$F:$F,'AM & AS'!$B:$B) -> 566.03226 | H43: =SUMIFS(TOKO!$J:$J,TOKO!$D:$D,'AM & AS'!$A:$A,TOKO!$F:$F,'AM & AS'!$B:$B) -> 0 | I43: =SUMIFS(TOKO!$K:$K,TOKO!$D:$D,'AM & AS'!$A:$A,TOKO!$F:$F,'AM & AS'!$B:$B) -> 27 | J43: =I43/G43*100 -> 4.7700462
A44: EGR | B44: SOSIS | C44: =COUNTIFS(TOKO!$D:$D,'AM & AS'!$A:$A,TOKO!$F:$F,'AM & AS'!$B:$B) -> 7 | D44: =COUNTIFS(TOKO!$D:$D,'AM & AS'!$A:$A,TOKO!$F:$F,'AM & AS'!$B:$B,TOKO!$K:$K,"=0") -> 0 | E44: =COUNTIFS(TOKO!$D:$D,'AM & AS'!$A:$A,TOKO!$F:$F,'AM & AS'!$B:$B,TOKO!$K:$K,">0") -> 0 | F44: =COUNTIFS(TOKO!$D:$D,'AM & AS'!$A:$A,TOKO!$F:$F,'AM & AS'!$B:$B,TOKO!$L:$L,"<100") -> 0 | G44: =SUMIFS(TOKO!$I:$I,TOKO!$D:$D,'AM & AS'!$A:$A,TOKO!$F:$F,'AM & AS'!$B:$B) -> 299.22623 | H44: =SUMIFS(TOKO!$J:$J,TOKO!$D:$D,'AM & AS'!$A:$A,TOKO!$F:$F,'AM & AS'!$B:$B) -> 0 | I44: =SUMIFS(TOKO!$K:$K,TOKO!$D:$D,'AM & AS'!$A:$A,TOKO!$F:$F,'AM & AS'!$B:$B) -> 0 | J44: =I44/G44*100 -> 0
A45: MBN | B45: SOSIS | C45: =COUNTIFS(TOKO!$D:$D,'AM & AS'!$A:$A,TOKO!$F:$F,'AM & AS'!$B:$B) -> 8 | D45: =COUNTIFS(TOKO!$D:$D,'AM & AS'!$A:$A,TOKO!$F:$F,'AM & AS'!$B:$B,TOKO!$K:$K,"=0") -> 0 | E45: =COUNTIFS(TOKO!$D:$D,'AM & AS'!$A:$A,TOKO!$F:$F,'AM & AS'!$B:$B,TOKO!$K:$K,">0") -> 0 | F45: =COUNTIFS(TOKO!$D:$D,'AM & AS'!$A:$A,TOKO!$F:$F,'AM & AS'!$B:$B,TOKO!$L:$L,"<100") -> 0 | G45: =SUMIFS(TOKO!$I:$I,TOKO!$D:$D,'AM & AS'!$A:$A,TOKO!$F:$F,'AM & AS'!$B:$B) -> 491.63766 | H45: =SUMIFS(TOKO!$J:$J,TOKO!$D:$D,'AM & AS'!$A:$A,TOKO!$F:$F,'AM & AS'!$B:$B) -> 0 | I45: =SUMIFS(TOKO!$K:$K,TOKO!$D:$D,'AM & AS'!$A:$A,TOKO!$F:$F,'AM & AS'!$B:$B) -> 0 | J45: =I45/G45*100 -> 0
A46: KHO | B46: FRIED CHICKEN | C46: =COUNTIFS(TOKO!$D:$D,'AM & AS'!$A:$A,TOKO!$F:$F,'AM & AS'!$B:$B) -> 11 | D46: =COUNTIFS(TOKO!$D:$D,'AM & AS'!$A:$A,TOKO!$F:$F,'AM & AS'!$B:$B,TOKO!$K:$K,"=0") -> 4 | E46: =COUNTIFS(TOKO!$D:$D,'AM & AS'!$A:$A,TOKO!$F:$F,'AM & AS'!$B:$B,TOKO!$K:$K,">0") -> 7 | F46: =COUNTIFS(TOKO!$D:$D,'AM & AS'!$A:$A,TOKO!$F:$F,'AM & AS'!$B:$B,TOKO!$L:$L,"<100") -> 11 | G46: =SUMIFS(TOKO!$I:$I,TOKO!$D:$D,'AM & AS'!$A:$A,TOKO!$F:$F,'AM & AS'!$B:$B) -> 459.48387 | H46: =SUMIFS(TOKO!$J:$J,TOKO!$D:$D,'AM & AS'!$A:$A,TOKO!$F:$F,'AM & AS'!$B:$B) -> 0 | I46: =SUMIFS(TOKO!$K:$K,TOKO!$D:$D,'AM & AS'!$A:$A,TOKO!$F:$F,'AM & AS'!$B:$B) -> 31 | J46: =I46/G46*100 -> 6.7467004
... A49: YRD | B49: SOSIS | C49: =COUNTIFS(TOKO!$D:$D,'AM & AS'!$A:$A,TOKO!$F:$F,'AM & AS'!$B:$B) -> 13 | D49: =COUNTIFS(TOKO!$D:$D,'AM & AS'!$A:$A,TOKO!$F:$F,'AM & AS'!$B:$B,TOKO!$K:$K,"=0") -> 0 | E49: =COUNTIFS(TOKO!$D:$D,'AM & AS'!$A:$A,TOKO!$F:$F,'AM & AS'!$B:$B,TOKO!$K:$K,">0") -> 0 | F49: =COUNTIFS(TOKO!$D:$D,'AM & AS'!$A:$A,TOKO!$F:$F,'AM & AS'!$B:$B,TOKO!$L:$L,"<100") -> 0 | G49: =SUMIFS(TOKO!$I:$I,TOKO!$D:$D,'AM & AS'!$A:$A,TOKO!$F:$F,'AM & AS'!$B:$B) -> 162.88064 | H49: =SUMIFS(TOKO!$J:$J,TOKO!$D:$D,'AM & AS'!$A:$A,TOKO!$F:$F,'AM & AS'!$B:$B) -> 0 | I49: =SUMIFS(TOKO!$K:$K,TOKO!$D:$D,'AM & AS'!$A:$A,TOKO!$F:$F,'AM & AS'!$B:$B) -> 0 | J49: =I49/G49*100 -> 0
A50: Grand Total | C50: =SUM(C35:C49) -> 148 | D50: =SUM(D35:D49) -> 27 | E50: =SUM(E35:E49) -> 36 | F50: =SUM(F35:F49) -> 63 | G50: =SUM(G35:G49) -> 4620.1441 | H50: =SUM(H35:H49) -> 0 | I50: =SUM(I35:I49) -> 187 | J50: =I50/G50*100 -> 4.0474928

Sheet TOKO
A1: REALTIME ICE CREAM & TELUR
A2: CAB JBR,KPG,SBA | F2: MODUL
A3: Kode Toko | B3: Nama Toko | C3: AM | D3: AS | E3: CABANG | F3: TYPE | G3: TYPE TOKO | H3: JAM | I3: TARGET | J3: STOK | K3: REALTIME | L3: ACH
A5: TG5D | B5: PENKASE NO. 28 ABC | C5: RFK | D5: =VLOOKUP($A5,[1]TOKO!$D$7:$R$594,12,) -> SGY | E5: KUPANG | F5: SOSIS | G5: STANDARD NEW | I5: 10
A6: TUI0 | B6: I. J. KASIMO | C6: RFK | D6: =VLOOKUP($A6,[1]TOKO!$D$7:$R$594,12,) -> PJO | E6: KUPANG | F6: SOSIS | G6: STANDARD | I6: 10
A7: TVB9 | B7: DIPONEGORO SOE | C7: RFK | D7: =VLOOKUP($A7,[1]TOKO!$D$7:$R$594,12,) -> RMB | E7: KUPANG | F7: SOSIS | G7: STANDARD | I7: 10
A8: TFMT | B8: RAYA MATANI | C8: JLE | D8: =VLOOKUP($A8,[1]TOKO!$D$7:$R$594,12,) -> KHO | E8: KUPANG | F8: SOSIS | G8: STANDARD | I8: 10
A9: TQTM | B9: SOEHARTO NO. 88 | C9: RFK | D9: =VLOOKUP($A9,[1]TOKO!$D$7:$R$594,12,) -> INK | E9: KUPANG | F9: SOSIS | G9: STANDARD NEW | I9: 10
A10: T47C | B10: HR KOROH SIKUMANA | C10: RFK | D10: =VLOOKUP($A10,[1]TOKO!$D$7:$R$594,12,) -> SGY | E10: KUPANG | F10: SOSIS | G10: STANDARD | I10: 10
A11: T2WX | B11: AMABI TOFA MAULAFA | C11: RFK | D11: =VLOOKUP($A11,[1]TOKO!$D$7:$R$594,12,) -> SGY | E11: KUPANG | F11: SOSIS | G11: STANDARD NEW | I11: 10
A12: TDHB | B12: TIMOR RAYA KELAPA LIMA | C12: RFK | D12: =VLOOKUP($A12,[1]TOKO!$D$7:$R$594,12,) -> INK | E12: KUPANG | F12: SOSIS | G12: STANDARD | I12: 10
A13: TTED | B13: HEREWILA | C13: JLE | D13: =VLOOKUP($A13,[1]TOKO!$D$7:$R$594,12,) -> YRD | E13: KUPANG | F13: SOSIS | G13: STANDARD | I13: 10
A14: TY7M | B14: ADI SUCIPTO | C14: JLE | D14: =VLOOKUP($A14,[1]TOKO!$D$7:$R$594,12,) -> YRD | E14: KUPANG | F14: SOSIS | G14: STANDARD | I14: 10
A15: TLN2 | B15: TIMOR RAYA KM 9 | C15: RFK | D15: =VLOOKUP($A15,[1]TOKO!$D$7:$R$594,12,) -> INK | E15: KUPANG | F15: SOSIS | G15: STANDARD | I15: 10
A16: T2JY | B16: LINTAS OINLASI | C16: RFK | D16: =VLOOKUP($A16,[1]TOKO!$D$7:$R$594,12,) -> RMB | E16: KUPANG | F16: SOSIS | G16: STANDARD | I16: 10
... A54: TJAX | B54: MARSDA ADI SUCIPTO TENUKIK | C54: RFK | D54: =VLOOKUP($A54,[1]TOKO!$D$7:$R$594,12,) -> PJO | E54: KUPANG | F54: SOSIS | G54: STANDARD | I54: 14.09475
A55: T53I | B55: TIMOR RAYA OESAPA KM 8 | C55: =VLOOKUP($A55,[2]TOKO!$D$7:$R$603,9,0) -> JLE | D55: =VLOOKUP($A55,[2]TOKO!$D$7:$R$603,12,0) -> KHO | E55: KUPANG | F55: FRIED CHICKEN | G55: STANDARD | H55: 11 | I55: 16.83871 | K55: =IFERROR(VLOOKUP($A55,[3]Sheet1!$A$2:$C$87,3,90),0) -> 0 | L55: =K55/I55*100 -> 0
A56: TG5Z | B56: ELTARI KM 7 | C56: =VLOOKUP($A56,[2]TOKO!$D$7:$R$603,9,0) -> RFK | D56: =VLOOKUP($A56,[2]TOKO!$D$7:$R$603,12,0) -> RMB | E56: KUPANG | F56: FRIED CHICKEN | G56: STANDARD | H56: 12 | I56: 14.322581 | K56: =IFERROR(VLOOKUP($A56,[3]Sheet1!$A$2:$C$87,3,90),0) -> 0 | L56: =K56/I56*100 -> 0
A57: TCGA | B57: FETOR FUNAY MAULAFA | C57: =VLOOKUP($A57,[2]TOKO!$D$7:$R$603,9,0) -> RFK | D57: =VLOOKUP($A57,[2]TOKO!$D$7:$R$603,12,0) -> SGY | E57: KUPANG | F57: FRIED CHICKEN | G57: STANDARD | H57: 12 | I57: 14.612903 | K57: =IFERROR(VLOOKUP($A57,[3]Sheet1!$A$2:$C$87,3,90),0) -> 0 | L57: =K57/I57*100 -> 0
A58: T0VA | B58: TIMOR RAYA KM 36 | C58: JLE | D58: =VLOOKUP($A58,[1]TOKO!$D$7:$R$594,12,) -> KHO | E58: KUPANG | F58: SOSIS | G58: STANDARD | I58: 14.603266
A59: TUI0 | B59: I. J. KASIMO | C59: =VLOOKUP($A59,[2]TOKO!$D$7:$R$603,9,0) -> RFK | D59: =VLOOKUP($A59,[2]TOKO!$D$7:$R$603,12,0) -> PJO | E59: KUPANG | F59: FRIED CHICKEN | G59: STANDARD | H59: 12 | I59: 16.354839 | K59: =IFERROR(VLOOKUP($A59,[3]Sheet1!$A$2:$C$87,3,90),0) -> 0 | L59: =K59/I59*100 -> 0
A60: TQ4M | B60: A. YANI TTU | C60: RFK | D60: =VLOOKUP($A60,[1]TOKO!$D$7:$R$594,12,) -> PJO | E60: KUPANG | F60: SOSIS | G60: STANDARD | I60: 14.726847
A61: TLNE | B61: RW MONGONSIDI | C61: =VLOOKUP($A61,[2]TOKO!$D$7:$R$603,9,0) -> JLE | D61: =VLOOKUP($A61,[2]TOKO!$D$7:$R$603,12,0) -> YRD | E61: KUPANG | F61: FRIED CHICKEN | G61: STANDARD | H61: 11 | I61: 34.258065 | K61: =IFERROR(VLOOKUP($A61,[3]Sheet1!$A$2:$C$87,3,90),0) -> 0 | L61: =K61/I61*100 -> 0
A62: TBRI | B62: W. J. LALAMENTIK OEBOBO | C62: =VLOOKUP($A62,[2]TOKO!$D$7:$R$603,9,0) -> RFK | D62: =VLOOKUP($A62,[2]TOKO!$D$7:$R$603,12,0) -> INK | E62: KUPANG | F62: FRIED CHICKEN | G62: STANDARD | H62: 12 | I62: 19.451613 | K62: =IFERROR(VLOOKUP($A62,[3]Sheet1!$A$2:$C$87,3,90),0) -> 0 | L62: =K62/I62*100 -> 0
A63: TTZQ | B63: PIET A TALLO OESAPA | C63: =VLOOKUP($A63,[2]TOKO!$D$7:$R$603,9,0) -> JLE | D63: =VLOOKUP($A63,[2]TOKO!$D$7:$R$603,12,0) -> KHO | E63: KUPANG | F63: FRIED CHICKEN | G63: STANDARD | H63: 11 | I63: 41.806452 | K63: =IFERROR(VLOOKUP($A63,[3]Sheet1!$A$2:$C$87,3,90),0) -> 0 | L63: =K63/I63*100 -> 0
A64: TLNE | B64: RW MONGONSIDI | C64: JLE | D64: =VLOOKUP($A64,[1]TOKO!$D$7:$R$594,12,) -> YRD | E64: KUPANG | F64: SOSIS | G64: STANDARD | I64: 15.439895
A65: T0VA | B65: TIMOR RAYA KM 36 | C65: =VLOOKUP($A65,[2]TOKO!$D$7:$R$603,9,0) -> JLE | D65: =VLOOKUP($A65,[2]TOKO!$D$7:$R$603,12,0) -> KHO | E65: KUPANG | F65: FRIED CHICKEN | G65: STANDARD | H65: 11 | I65: 46.741935 | K65: =IFERROR(VLOOKUP($A65,[3]Sheet1!$A$2:$C$87,3,90),0) -> 0 | L65: =K65/I65*100 -> 0
A66: TUXZ | B66: PRAILIU SUMBA | C66: =VLOOKUP($A66,[2]TOKO!$D$7:$R$603,9,0) -> JLE | D66: =VLOOKUP($A66,[2]TOKO!$D$7:$R$603,12,0) -> EGR | E66: SUMBA | F66: FRIED CHICKEN | G66: STANDARD | H66: 11 | I66: 79.064516 | K66: =IFERROR(VLOOKUP($A66,[3]Sheet1!$A$2:$C$87,3,90),0) -> 0 | L66: =K66/I66*100 -> 0
A67: TS7P | B67: PAHLAWAN NUNBAUN SABU | C67: RFK | D67: =VLOOKUP($A67,[1]TOKO!$D$7:$R$594,12,) -> SGY | E67: KUPANG | F67: SOSIS | G67: STANDARD | I67: 16.004371
A68: TXQN | B68: RAYA ANAKALANG | C68: =VLOOKUP($A68,[2]TOKO!$D$7:$R$603,9,0) -> JLE | D68: =VLOOKUP($A68,[2]TOKO!$D$7:$R$603,12,0) -> EGR | E68: SUMBA | F68: FRIED CHICKEN | G68: STANDARD | H68: 11 | I68: 99.870968 | K68: =IFERROR(VLOOKUP($A68,[3]Sheet1!$A$2:$C$87,3,90),0) -> 0 | L68: =K68/I68*100 -> 0
A69: T2ZE | B69: FATUBESI KUPANG | C69: =VLOOKUP($A69,[2]TOKO!$D$7:$R$603,9,0) -> JLE | D69: =VLOOKUP($A69,[2]TOKO!$D$7:$R$603,12,0) -> YRD | E69: KUPANG | F69: FRIED CHICKEN | G69: STANDARD | H69: 11 | I69: 26.516129 | K69: =IFERROR(VLOOKUP($A69,[3]Sheet1!$A$2:$C$87,3,90),0) -> 0 | L69: =K69/I69*100 -> 0
A70: T5R3 | B70: JEND. SOEHARTO NO. 66 | C70: RFK | D70: =VLOOKUP($A70,[1]TOKO!$D$7:$R$594,12,) -> INK | E70: KUPANG | F70: SOSIS | G70: STANDARD | I70: 17.618444
A71: TTZQ | B71: PIET A TALLO OESAPA | C71: JLE | D71: =VLOOKUP($A71,[1]TOKO!$D$7:$R$594,12,) -> KHO | E71: KUPANG | F71: SOSIS | G71: STANDARD | I71: 17.967145
A72: TVJX | B72: WJ LALAMENTIK OEBUFU - KPG | C72: RFK | D72: =VLOOKUP($A72,[1]TOKO!$D$7:$R$594,12,) -> SGY | E72: KUPANG | F72: SOSIS | G72: STANDARD NEW | I72: 18.159847
A73: TE9I | B73: A. YANI SOE | C73: RFK | D73: =VLOOKUP($A73,[1]TOKO!$D$7:$R$594,12,) -> RMB | E73: KUPANG | F73: SOSIS | G73: STANDARD | I73: 18.235992
A74: T0KG | B74: TIMOR RAYA KM 14 | C74: =VLOOKUP($A74,[2]TOKO!$D$7:$R$603,9,0) -> JLE | D74: =VLOOKUP($A74,[2]TOKO!$D$7:$R$603,12,0) -> KHO | E74: KUPANG | F74: FRIED CHICKEN | G74: STANDARD | H74: 11 | I74: 36.580645 | K74: =IFERROR(VLOOKUP($A74,[3]Sheet1!$A$2:$C$87,3,90),0) -> 0 | L74: =K74/I74*100 -> 0
A75: T1WS | B75: A. YANI MERDEKA | C75: JLE | D75: =VLOOKUP($A75,[1]TOKO!$D$7:$R$594,12,) -> KHO | E75: KUPANG | F75: SOSIS | G75: STANDARD | I75: 19.582113
A76: TTED | B76: HEREWILA | C76: =VLOOKUP($A76,[2]TOKO!$D$7:$R$603,9,0) -> JLE | D76: =VLOOKUP($A76,[2]TOKO!$D$7:$R$603,12,0) -> YRD | E76: KUPANG | F76: FRIED CHICKEN | G76: STANDARD | H76: 11 | I76: 15 | K76: =IFERROR(VLOOKUP($A76,[3]Sheet1!$A$2:$C$87,3,90),0) -> 0 | L76: =K76/I76*100 -> 0
A77: TT1V | B77: TR NOELBAKI KUPANG | C77: JLE | D77: =VLOOKUP($A77,[1]TOKO!$D$7:$R$594,12,) -> KHO | E77: KUPANG | F77: SOSIS | G77: STANDARD | I77: 20.393798
A78: T6AH | B78: HAYAM WURUK SOE | C78: RFK | D78: =VLOOKUP($A78,[1]TOKO!$D$7:$R$594,12,) -> RMB | E78: KUPANG | F78: SOSIS | G78: STANDARD | I78: 20.611774
...
